2022-02-17 10:17:28,374 - apscheduler.scheduler - INFO - Scheduler started
2022-02-17 10:20:12,073 - apscheduler.scheduler - INFO - Scheduler started
2022-02-17 10:27:03,007 - apscheduler.scheduler - INFO - Scheduler started
2022-02-17 10:31:50,214 - telegram.ext.dispatcher - ERROR - An uncaught error was raised while handling the error.
Traceback (most recent call last):
  File "C:\Users\STUD\AppData\Local\Programs\Python\Python37\lib\site-packages\telegram\ext\dispatcher.py", line 555, in process_update
    handler.handle_update(update, self, check, context)
  File "C:\Users\STUD\AppData\Local\Programs\Python\Python37\lib\site-packages\telegram\ext\handler.py", line 198, in handle_update
    return self.callback(update, context)
  File "C:/Users/STUD/Documents/GitHub/BCA-SEM-6/PROGRAM/PYTHON/telebot/telebot.py", line 59, in insert
    user = update.message.from_user
AttributeError: 'CallbackContext' object has no attribute 'message'

During handling of the above exception, another exception occurred:

Traceback (most recent call last):
  File "C:\Users\STUD\AppData\Local\Programs\Python\Python37\lib\site-packages\telegram\ext\dispatcher.py", line 567, in process_update
    self.dispatch_error(update, exc)
  File "C:\Users\STUD\AppData\Local\Programs\Python\Python37\lib\site-packages\telegram\ext\dispatcher.py", line 810, in dispatch_error
    callback(update, context)
TypeError: error() missing 1 required positional argument: 'error'
2022-02-17 10:31:58,763 - telegram.ext.dispatcher - ERROR - An uncaught error was raised while handling the error.
Traceback (most recent call last):
  File "C:\Users\STUD\AppData\Local\Programs\Python\Python37\lib\site-packages\telegram\ext\dispatcher.py", line 555, in process_update
    handler.handle_update(update, self, check, context)
  File "C:\Users\STUD\AppData\Local\Programs\Python\Python37\lib\site-packages\telegram\ext\handler.py", line 198, in handle_update
    return self.callback(update, context)
  File "C:/Users/STUD/Documents/GitHub/BCA-SEM-6/PROGRAM/PYTHON/telebot/telebot.py", line 54, in start
    user = update.message.from_user
AttributeError: 'CallbackContext' object has no attribute 'message'

During handling of the above exception, another exception occurred:

Traceback (most recent call last):
  File "C:\Users\STUD\AppData\Local\Programs\Python\Python37\lib\site-packages\telegram\ext\dispatcher.py", line 567, in process_update
    self.dispatch_error(update, exc)
  File "C:\Users\STUD\AppData\Local\Programs\Python\Python37\lib\site-packages\telegram\ext\dispatcher.py", line 810, in dispatch_error
    callback(update, context)
TypeError: error() missing 1 required positional argument: 'error'
2022-02-17 11:03:34,868 - apscheduler.scheduler - INFO - Scheduler started
2022-02-17 11:06:58,344 - telegram.ext.dispatcher - ERROR - An uncaught error was raised while handling the error.
Traceback (most recent call last):
  File "C:\Users\STUD\AppData\Local\Programs\Python\Python37\lib\site-packages\telegram\ext\dispatcher.py", line 555, in process_update
    handler.handle_update(update, self, check, context)
  File "C:\Users\STUD\AppData\Local\Programs\Python\Python37\lib\site-packages\telegram\ext\handler.py", line 198, in handle_update
    return self.callback(update, context)
  File "C:/Users/STUD/Documents/GitHub/BCA-SEM-6/PROGRAM/PYTHON/telebot/telebot.py", line 53, in start
    user = update.message.from_user
AttributeError: 'CallbackContext' object has no attribute 'message'

During handling of the above exception, another exception occurred:

Traceback (most recent call last):
  File "C:\Users\STUD\AppData\Local\Programs\Python\Python37\lib\site-packages\telegram\ext\dispatcher.py", line 567, in process_update
    self.dispatch_error(update, exc)
  File "C:\Users\STUD\AppData\Local\Programs\Python\Python37\lib\site-packages\telegram\ext\dispatcher.py", line 810, in dispatch_error
    callback(update, context)
TypeError: error() missing 1 required positional argument: 'error'
2022-02-17 11:07:36,049 - telegram.ext.dispatcher - ERROR - An uncaught error was raised while handling the error.
Traceback (most recent call last):
  File "C:\Users\STUD\AppData\Local\Programs\Python\Python37\lib\site-packages\telegram\ext\dispatcher.py", line 555, in process_update
    handler.handle_update(update, self, check, context)
  File "C:\Users\STUD\AppData\Local\Programs\Python\Python37\lib\site-packages\telegram\ext\handler.py", line 198, in handle_update
    return self.callback(update, context)
  File "C:/Users/STUD/Documents/GitHub/BCA-SEM-6/PROGRAM/PYTHON/telebot/telebot.py", line 53, in start
    user = update.message.from_user
AttributeError: 'CallbackContext' object has no attribute 'message'

During handling of the above exception, another exception occurred:

Traceback (most recent call last):
  File "C:\Users\STUD\AppData\Local\Programs\Python\Python37\lib\site-packages\telegram\ext\dispatcher.py", line 567, in process_update
    self.dispatch_error(update, exc)
  File "C:\Users\STUD\AppData\Local\Programs\Python\Python37\lib\site-packages\telegram\ext\dispatcher.py", line 810, in dispatch_error
    callback(update, context)
TypeError: error() missing 1 required positional argument: 'error'
2022-02-17 11:08:20,334 - apscheduler.scheduler - INFO - Scheduler started
2022-02-17 11:08:34,378 - apscheduler.scheduler - INFO - Scheduler started
2022-02-17 11:08:44,758 - telegram.ext.dispatcher - ERROR - An uncaught error was raised while handling the error.
Traceback (most recent call last):
  File "C:\Users\STUD\AppData\Local\Programs\Python\Python37\lib\site-packages\telegram\ext\dispatcher.py", line 555, in process_update
    handler.handle_update(update, self, check, context)
  File "C:\Users\STUD\AppData\Local\Programs\Python\Python37\lib\site-packages\telegram\ext\handler.py", line 198, in handle_update
    return self.callback(update, context)
  File "C:/Users/STUD/Documents/GitHub/BCA-SEM-6/PROGRAM/PYTHON/telebot/telebot.py", line 53, in start
    user = update.message.from_user
AttributeError: 'CallbackContext' object has no attribute 'message'

During handling of the above exception, another exception occurred:

Traceback (most recent call last):
  File "C:\Users\STUD\AppData\Local\Programs\Python\Python37\lib\site-packages\telegram\ext\dispatcher.py", line 567, in process_update
    self.dispatch_error(update, exc)
  File "C:\Users\STUD\AppData\Local\Programs\Python\Python37\lib\site-packages\telegram\ext\dispatcher.py", line 810, in dispatch_error
    callback(update, context)
TypeError: error() missing 1 required positional argument: 'error'
2022-02-17 11:08:47,435 - telegram.ext.dispatcher - ERROR - An uncaught error was raised while handling the error.
Traceback (most recent call last):
  File "C:\Users\STUD\AppData\Local\Programs\Python\Python37\lib\site-packages\telegram\ext\dispatcher.py", line 555, in process_update
    handler.handle_update(update, self, check, context)
  File "C:\Users\STUD\AppData\Local\Programs\Python\Python37\lib\site-packages\telegram\ext\handler.py", line 198, in handle_update
    return self.callback(update, context)
  File "C:/Users/STUD/Documents/GitHub/BCA-SEM-6/PROGRAM/PYTHON/telebot/telebot.py", line 53, in start
    user = update.message.from_user
AttributeError: 'CallbackContext' object has no attribute 'message'

During handling of the above exception, another exception occurred:

Traceback (most recent call last):
  File "C:\Users\STUD\AppData\Local\Programs\Python\Python37\lib\site-packages\telegram\ext\dispatcher.py", line 567, in process_update
    self.dispatch_error(update, exc)
  File "C:\Users\STUD\AppData\Local\Programs\Python\Python37\lib\site-packages\telegram\ext\dispatcher.py", line 810, in dispatch_error
    callback(update, context)
TypeError: error() missing 1 required positional argument: 'error'
2022-02-17 11:08:47,932 - telegram.ext.dispatcher - ERROR - An uncaught error was raised while handling the error.
Traceback (most recent call last):
  File "C:\Users\STUD\AppData\Local\Programs\Python\Python37\lib\site-packages\telegram\ext\dispatcher.py", line 555, in process_update
    handler.handle_update(update, self, check, context)
  File "C:\Users\STUD\AppData\Local\Programs\Python\Python37\lib\site-packages\telegram\ext\handler.py", line 198, in handle_update
    return self.callback(update, context)
  File "C:/Users/STUD/Documents/GitHub/BCA-SEM-6/PROGRAM/PYTHON/telebot/telebot.py", line 53, in start
    user = update.message.from_user
AttributeError: 'CallbackContext' object has no attribute 'message'

During handling of the above exception, another exception occurred:

Traceback (most recent call last):
  File "C:\Users\STUD\AppData\Local\Programs\Python\Python37\lib\site-packages\telegram\ext\dispatcher.py", line 567, in process_update
    self.dispatch_error(update, exc)
  File "C:\Users\STUD\AppData\Local\Programs\Python\Python37\lib\site-packages\telegram\ext\dispatcher.py", line 810, in dispatch_error
    callback(update, context)
TypeError: error() missing 1 required positional argument: 'error'
2022-02-17 11:10:06,519 - apscheduler.scheduler - INFO - Scheduler started
2022-02-17 11:10:11,015 - telegram.ext.dispatcher - ERROR - An uncaught error was raised while handling the error.
Traceback (most recent call last):
  File "C:\Users\STUD\AppData\Local\Programs\Python\Python37\lib\site-packages\telegram\ext\dispatcher.py", line 555, in process_update
    handler.handle_update(update, self, check, context)
  File "C:\Users\STUD\AppData\Local\Programs\Python\Python37\lib\site-packages\telegram\ext\handler.py", line 198, in handle_update
    return self.callback(update, context)
  File "C:/Users/STUD/Documents/GitHub/BCA-SEM-6/PROGRAM/PYTHON/telebot/telebot.py", line 53, in start
    user = update.message.from_user
AttributeError: 'CallbackContext' object has no attribute 'message'

During handling of the above exception, another exception occurred:

Traceback (most recent call last):
  File "C:\Users\STUD\AppData\Local\Programs\Python\Python37\lib\site-packages\telegram\ext\dispatcher.py", line 567, in process_update
    self.dispatch_error(update, exc)
  File "C:\Users\STUD\AppData\Local\Programs\Python\Python37\lib\site-packages\telegram\ext\dispatcher.py", line 810, in dispatch_error
    callback(update, context)
TypeError: error() missing 1 required positional argument: 'error'
2022-02-17 11:10:11,736 - telegram.ext.dispatcher - ERROR - An uncaught error was raised while handling the error.
Traceback (most recent call last):
  File "C:\Users\STUD\AppData\Local\Programs\Python\Python37\lib\site-packages\telegram\ext\dispatcher.py", line 555, in process_update
    handler.handle_update(update, self, check, context)
  File "C:\Users\STUD\AppData\Local\Programs\Python\Python37\lib\site-packages\telegram\ext\handler.py", line 198, in handle_update
    return self.callback(update, context)
  File "C:/Users/STUD/Documents/GitHub/BCA-SEM-6/PROGRAM/PYTHON/telebot/telebot.py", line 53, in start
    user = update.message.from_user
AttributeError: 'CallbackContext' object has no attribute 'message'

During handling of the above exception, another exception occurred:

Traceback (most recent call last):
  File "C:\Users\STUD\AppData\Local\Programs\Python\Python37\lib\site-packages\telegram\ext\dispatcher.py", line 567, in process_update
    self.dispatch_error(update, exc)
  File "C:\Users\STUD\AppData\Local\Programs\Python\Python37\lib\site-packages\telegram\ext\dispatcher.py", line 810, in dispatch_error
    callback(update, context)
TypeError: error() missing 1 required positional argument: 'error'
2022-02-17 11:10:12,050 - telegram.ext.dispatcher - ERROR - An uncaught error was raised while handling the error.
Traceback (most recent call last):
  File "C:\Users\STUD\AppData\Local\Programs\Python\Python37\lib\site-packages\telegram\ext\dispatcher.py", line 555, in process_update
    handler.handle_update(update, self, check, context)
  File "C:\Users\STUD\AppData\Local\Programs\Python\Python37\lib\site-packages\telegram\ext\handler.py", line 198, in handle_update
    return self.callback(update, context)
  File "C:/Users/STUD/Documents/GitHub/BCA-SEM-6/PROGRAM/PYTHON/telebot/telebot.py", line 53, in start
    user = update.message.from_user
AttributeError: 'CallbackContext' object has no attribute 'message'

During handling of the above exception, another exception occurred:

Traceback (most recent call last):
  File "C:\Users\STUD\AppData\Local\Programs\Python\Python37\lib\site-packages\telegram\ext\dispatcher.py", line 567, in process_update
    self.dispatch_error(update, exc)
  File "C:\Users\STUD\AppData\Local\Programs\Python\Python37\lib\site-packages\telegram\ext\dispatcher.py", line 810, in dispatch_error
    callback(update, context)
TypeError: error() missing 1 required positional argument: 'error'
2022-02-17 11:10:16,219 - telegram.ext.dispatcher - ERROR - An uncaught error was raised while handling the error.
Traceback (most recent call last):
  File "C:\Users\STUD\AppData\Local\Programs\Python\Python37\lib\site-packages\telegram\ext\dispatcher.py", line 555, in process_update
    handler.handle_update(update, self, check, context)
  File "C:\Users\STUD\AppData\Local\Programs\Python\Python37\lib\site-packages\telegram\ext\handler.py", line 198, in handle_update
    return self.callback(update, context)
  File "C:/Users/STUD/Documents/GitHub/BCA-SEM-6/PROGRAM/PYTHON/telebot/telebot.py", line 53, in start
    user = update.message.from_user
AttributeError: 'CallbackContext' object has no attribute 'message'

During handling of the above exception, another exception occurred:

Traceback (most recent call last):
  File "C:\Users\STUD\AppData\Local\Programs\Python\Python37\lib\site-packages\telegram\ext\dispatcher.py", line 567, in process_update
    self.dispatch_error(update, exc)
  File "C:\Users\STUD\AppData\Local\Programs\Python\Python37\lib\site-packages\telegram\ext\dispatcher.py", line 810, in dispatch_error
    callback(update, context)
TypeError: error() missing 1 required positional argument: 'error'
2022-02-17 11:11:26,974 - apscheduler.scheduler - INFO - Scheduler started
2022-02-17 11:11:31,523 - telegram.ext.dispatcher - ERROR - An uncaught error was raised while handling the error.
Traceback (most recent call last):
  File "C:\Users\STUD\AppData\Local\Programs\Python\Python37\lib\site-packages\telegram\ext\dispatcher.py", line 555, in process_update
    handler.handle_update(update, self, check, context)
  File "C:\Users\STUD\AppData\Local\Programs\Python\Python37\lib\site-packages\telegram\ext\handler.py", line 198, in handle_update
    return self.callback(update, context)
  File "C:/Users/STUD/Documents/GitHub/BCA-SEM-6/PROGRAM/PYTHON/telebot/telebot.py", line 54, in start
    user = update.message.from_user
AttributeError: 'CallbackContext' object has no attribute 'message'

During handling of the above exception, another exception occurred:

Traceback (most recent call last):
  File "C:\Users\STUD\AppData\Local\Programs\Python\Python37\lib\site-packages\telegram\ext\dispatcher.py", line 567, in process_update
    self.dispatch_error(update, exc)
  File "C:\Users\STUD\AppData\Local\Programs\Python\Python37\lib\site-packages\telegram\ext\dispatcher.py", line 810, in dispatch_error
    callback(update, context)
TypeError: error() missing 1 required positional argument: 'error'
2022-02-17 11:11:32,036 - telegram.ext.dispatcher - ERROR - An uncaught error was raised while handling the error.
Traceback (most recent call last):
  File "C:\Users\STUD\AppData\Local\Programs\Python\Python37\lib\site-packages\telegram\ext\dispatcher.py", line 555, in process_update
    handler.handle_update(update, self, check, context)
  File "C:\Users\STUD\AppData\Local\Programs\Python\Python37\lib\site-packages\telegram\ext\handler.py", line 198, in handle_update
    return self.callback(update, context)
  File "C:/Users/STUD/Documents/GitHub/BCA-SEM-6/PROGRAM/PYTHON/telebot/telebot.py", line 54, in start
    user = update.message.from_user
AttributeError: 'CallbackContext' object has no attribute 'message'

During handling of the above exception, another exception occurred:

Traceback (most recent call last):
  File "C:\Users\STUD\AppData\Local\Programs\Python\Python37\lib\site-packages\telegram\ext\dispatcher.py", line 567, in process_update
    self.dispatch_error(update, exc)
  File "C:\Users\STUD\AppData\Local\Programs\Python\Python37\lib\site-packages\telegram\ext\dispatcher.py", line 810, in dispatch_error
    callback(update, context)
TypeError: error() missing 1 required positional argument: 'error'
2022-02-17 11:12:31,260 - apscheduler.scheduler - INFO - Scheduler started
2022-02-17 11:12:34,104 - telegram.ext.dispatcher - ERROR - An uncaught error was raised while handling the error.
Traceback (most recent call last):
  File "C:\Users\STUD\AppData\Local\Programs\Python\Python37\lib\site-packages\telegram\ext\dispatcher.py", line 555, in process_update
    handler.handle_update(update, self, check, context)
  File "C:\Users\STUD\AppData\Local\Programs\Python\Python37\lib\site-packages\telegram\ext\handler.py", line 198, in handle_update
    return self.callback(update, context)
  File "C:/Users/STUD/Documents/GitHub/BCA-SEM-6/PROGRAM/PYTHON/telebot/telebot.py", line 54, in start
    user = update.message.from_user
AttributeError: 'CallbackContext' object has no attribute 'message'

During handling of the above exception, another exception occurred:

Traceback (most recent call last):
  File "C:\Users\STUD\AppData\Local\Programs\Python\Python37\lib\site-packages\telegram\ext\dispatcher.py", line 567, in process_update
    self.dispatch_error(update, exc)
  File "C:\Users\STUD\AppData\Local\Programs\Python\Python37\lib\site-packages\telegram\ext\dispatcher.py", line 810, in dispatch_error
    callback(update, context)
TypeError: error() missing 1 required positional argument: 'error'
2022-02-17 11:12:34,443 - telegram.ext.dispatcher - ERROR - An uncaught error was raised while handling the error.
Traceback (most recent call last):
  File "C:\Users\STUD\AppData\Local\Programs\Python\Python37\lib\site-packages\telegram\ext\dispatcher.py", line 555, in process_update
    handler.handle_update(update, self, check, context)
  File "C:\Users\STUD\AppData\Local\Programs\Python\Python37\lib\site-packages\telegram\ext\handler.py", line 198, in handle_update
    return self.callback(update, context)
  File "C:/Users/STUD/Documents/GitHub/BCA-SEM-6/PROGRAM/PYTHON/telebot/telebot.py", line 54, in start
    user = update.message.from_user
AttributeError: 'CallbackContext' object has no attribute 'message'

During handling of the above exception, another exception occurred:

Traceback (most recent call last):
  File "C:\Users\STUD\AppData\Local\Programs\Python\Python37\lib\site-packages\telegram\ext\dispatcher.py", line 567, in process_update
    self.dispatch_error(update, exc)
  File "C:\Users\STUD\AppData\Local\Programs\Python\Python37\lib\site-packages\telegram\ext\dispatcher.py", line 810, in dispatch_error
    callback(update, context)
TypeError: error() missing 1 required positional argument: 'error'
2022-02-17 11:13:20,711 - apscheduler.scheduler - INFO - Scheduler started
2022-02-17 11:13:31,302 - telegram.ext.dispatcher - ERROR - An uncaught error was raised while handling the error.
Traceback (most recent call last):
  File "C:\Users\STUD\AppData\Local\Programs\Python\Python37\lib\site-packages\telegram\ext\dispatcher.py", line 555, in process_update
    handler.handle_update(update, self, check, context)
  File "C:\Users\STUD\AppData\Local\Programs\Python\Python37\lib\site-packages\telegram\ext\handler.py", line 198, in handle_update
    return self.callback(update, context)
  File "C:/Users/STUD/Documents/GitHub/BCA-SEM-6/PROGRAM/PYTHON/telebot/telebot.py", line 54, in start
    user = update.message.from_user
AttributeError: 'CallbackContext' object has no attribute 'message'

During handling of the above exception, another exception occurred:

Traceback (most recent call last):
  File "C:\Users\STUD\AppData\Local\Programs\Python\Python37\lib\site-packages\telegram\ext\dispatcher.py", line 567, in process_update
    self.dispatch_error(update, exc)
  File "C:\Users\STUD\AppData\Local\Programs\Python\Python37\lib\site-packages\telegram\ext\dispatcher.py", line 810, in dispatch_error
    callback(update, context)
TypeError: error() missing 1 required positional argument: 'error'
2022-02-17 11:13:31,591 - telegram.ext.dispatcher - ERROR - An uncaught error was raised while handling the error.
Traceback (most recent call last):
  File "C:\Users\STUD\AppData\Local\Programs\Python\Python37\lib\site-packages\telegram\ext\dispatcher.py", line 555, in process_update
    handler.handle_update(update, self, check, context)
  File "C:\Users\STUD\AppData\Local\Programs\Python\Python37\lib\site-packages\telegram\ext\handler.py", line 198, in handle_update
    return self.callback(update, context)
  File "C:/Users/STUD/Documents/GitHub/BCA-SEM-6/PROGRAM/PYTHON/telebot/telebot.py", line 54, in start
    user = update.message.from_user
AttributeError: 'CallbackContext' object has no attribute 'message'

During handling of the above exception, another exception occurred:

Traceback (most recent call last):
  File "C:\Users\STUD\AppData\Local\Programs\Python\Python37\lib\site-packages\telegram\ext\dispatcher.py", line 567, in process_update
    self.dispatch_error(update, exc)
  File "C:\Users\STUD\AppData\Local\Programs\Python\Python37\lib\site-packages\telegram\ext\dispatcher.py", line 810, in dispatch_error
    callback(update, context)
TypeError: error() missing 1 required positional argument: 'error'
2022-02-17 11:14:40,833 - apscheduler.scheduler - INFO - Scheduler started
2022-02-17 11:14:43,301 - telegram.ext.dispatcher - ERROR - An uncaught error was raised while handling the error.
Traceback (most recent call last):
  File "C:\Users\STUD\AppData\Local\Programs\Python\Python37\lib\site-packages\telegram\ext\dispatcher.py", line 555, in process_update
    handler.handle_update(update, self, check, context)
  File "C:\Users\STUD\AppData\Local\Programs\Python\Python37\lib\site-packages\telegram\ext\handler.py", line 198, in handle_update
    return self.callback(update, context)
  File "C:/Users/STUD/Documents/GitHub/BCA-SEM-6/PROGRAM/PYTHON/telebot/telebot.py", line 54, in start
    update.message.reply_text(u'Welcome to the best Url shortener\nJust send me a link and I\'ll shorten it.')
AttributeError: 'CallbackContext' object has no attribute 'message'

During handling of the above exception, another exception occurred:

Traceback (most recent call last):
  File "C:\Users\STUD\AppData\Local\Programs\Python\Python37\lib\site-packages\telegram\ext\dispatcher.py", line 567, in process_update
    self.dispatch_error(update, exc)
  File "C:\Users\STUD\AppData\Local\Programs\Python\Python37\lib\site-packages\telegram\ext\dispatcher.py", line 810, in dispatch_error
    callback(update, context)
TypeError: error() missing 1 required positional argument: 'error'
2022-02-17 11:14:48,639 - telegram.ext.dispatcher - ERROR - An uncaught error was raised while handling the error.
Traceback (most recent call last):
  File "C:\Users\STUD\AppData\Local\Programs\Python\Python37\lib\site-packages\telegram\ext\dispatcher.py", line 555, in process_update
    handler.handle_update(update, self, check, context)
  File "C:\Users\STUD\AppData\Local\Programs\Python\Python37\lib\site-packages\telegram\ext\handler.py", line 198, in handle_update
    return self.callback(update, context)
  File "C:/Users/STUD/Documents/GitHub/BCA-SEM-6/PROGRAM/PYTHON/telebot/telebot.py", line 58, in insert
    user = update.message.from_user
AttributeError: 'CallbackContext' object has no attribute 'message'

During handling of the above exception, another exception occurred:

Traceback (most recent call last):
  File "C:\Users\STUD\AppData\Local\Programs\Python\Python37\lib\site-packages\telegram\ext\dispatcher.py", line 567, in process_update
    self.dispatch_error(update, exc)
  File "C:\Users\STUD\AppData\Local\Programs\Python\Python37\lib\site-packages\telegram\ext\dispatcher.py", line 810, in dispatch_error
    callback(update, context)
TypeError: error() missing 1 required positional argument: 'error'
2022-02-17 11:14:54,784 - telegram.ext.dispatcher - ERROR - An uncaught error was raised while handling the error.
Traceback (most recent call last):
  File "C:\Users\STUD\AppData\Local\Programs\Python\Python37\lib\site-packages\telegram\ext\dispatcher.py", line 555, in process_update
    handler.handle_update(update, self, check, context)
  File "C:\Users\STUD\AppData\Local\Programs\Python\Python37\lib\site-packages\telegram\ext\handler.py", line 198, in handle_update
    return self.callback(update, context)
  File "C:/Users/STUD/Documents/GitHub/BCA-SEM-6/PROGRAM/PYTHON/telebot/telebot.py", line 54, in start
    update.message.reply_text(u'Welcome to the best Url shortener\nJust send me a link and I\'ll shorten it.')
AttributeError: 'CallbackContext' object has no attribute 'message'

During handling of the above exception, another exception occurred:

Traceback (most recent call last):
  File "C:\Users\STUD\AppData\Local\Programs\Python\Python37\lib\site-packages\telegram\ext\dispatcher.py", line 567, in process_update
    self.dispatch_error(update, exc)
  File "C:\Users\STUD\AppData\Local\Programs\Python\Python37\lib\site-packages\telegram\ext\dispatcher.py", line 810, in dispatch_error
    callback(update, context)
TypeError: error() missing 1 required positional argument: 'error'
2022-02-17 11:14:57,225 - telegram.ext.dispatcher - ERROR - An uncaught error was raised while handling the error.
Traceback (most recent call last):
  File "C:\Users\STUD\AppData\Local\Programs\Python\Python37\lib\site-packages\telegram\ext\dispatcher.py", line 555, in process_update
    handler.handle_update(update, self, check, context)
  File "C:\Users\STUD\AppData\Local\Programs\Python\Python37\lib\site-packages\telegram\ext\handler.py", line 198, in handle_update
    return self.callback(update, context)
  File "C:/Users/STUD/Documents/GitHub/BCA-SEM-6/PROGRAM/PYTHON/telebot/telebot.py", line 54, in start
    update.message.reply_text(u'Welcome to the best Url shortener\nJust send me a link and I\'ll shorten it.')
AttributeError: 'CallbackContext' object has no attribute 'message'

During handling of the above exception, another exception occurred:

Traceback (most recent call last):
  File "C:\Users\STUD\AppData\Local\Programs\Python\Python37\lib\site-packages\telegram\ext\dispatcher.py", line 567, in process_update
    self.dispatch_error(update, exc)
  File "C:\Users\STUD\AppData\Local\Programs\Python\Python37\lib\site-packages\telegram\ext\dispatcher.py", line 810, in dispatch_error
    callback(update, context)
TypeError: error() missing 1 required positional argument: 'error'
2022-02-17 11:14:58,390 - telegram.ext.dispatcher - ERROR - An uncaught error was raised while handling the error.
Traceback (most recent call last):
  File "C:\Users\STUD\AppData\Local\Programs\Python\Python37\lib\site-packages\telegram\ext\dispatcher.py", line 555, in process_update
    handler.handle_update(update, self, check, context)
  File "C:\Users\STUD\AppData\Local\Programs\Python\Python37\lib\site-packages\telegram\ext\handler.py", line 198, in handle_update
    return self.callback(update, context)
  File "C:/Users/STUD/Documents/GitHub/BCA-SEM-6/PROGRAM/PYTHON/telebot/telebot.py", line 54, in start
    update.message.reply_text(u'Welcome to the best Url shortener\nJust send me a link and I\'ll shorten it.')
AttributeError: 'CallbackContext' object has no attribute 'message'

During handling of the above exception, another exception occurred:

Traceback (most recent call last):
  File "C:\Users\STUD\AppData\Local\Programs\Python\Python37\lib\site-packages\telegram\ext\dispatcher.py", line 567, in process_update
    self.dispatch_error(update, exc)
  File "C:\Users\STUD\AppData\Local\Programs\Python\Python37\lib\site-packages\telegram\ext\dispatcher.py", line 810, in dispatch_error
    callback(update, context)
TypeError: error() missing 1 required positional argument: 'error'
2022-02-17 11:14:58,898 - telegram.ext.dispatcher - ERROR - An uncaught error was raised while handling the error.
Traceback (most recent call last):
  File "C:\Users\STUD\AppData\Local\Programs\Python\Python37\lib\site-packages\telegram\ext\dispatcher.py", line 555, in process_update
    handler.handle_update(update, self, check, context)
  File "C:\Users\STUD\AppData\Local\Programs\Python\Python37\lib\site-packages\telegram\ext\handler.py", line 198, in handle_update
    return self.callback(update, context)
  File "C:/Users/STUD/Documents/GitHub/BCA-SEM-6/PROGRAM/PYTHON/telebot/telebot.py", line 54, in start
    update.message.reply_text(u'Welcome to the best Url shortener\nJust send me a link and I\'ll shorten it.')
AttributeError: 'CallbackContext' object has no attribute 'message'

During handling of the above exception, another exception occurred:

Traceback (most recent call last):
  File "C:\Users\STUD\AppData\Local\Programs\Python\Python37\lib\site-packages\telegram\ext\dispatcher.py", line 567, in process_update
    self.dispatch_error(update, exc)
  File "C:\Users\STUD\AppData\Local\Programs\Python\Python37\lib\site-packages\telegram\ext\dispatcher.py", line 810, in dispatch_error
    callback(update, context)
TypeError: error() missing 1 required positional argument: 'error'
2022-02-17 11:14:59,507 - telegram.ext.dispatcher - ERROR - An uncaught error was raised while handling the error.
Traceback (most recent call last):
  File "C:\Users\STUD\AppData\Local\Programs\Python\Python37\lib\site-packages\telegram\ext\dispatcher.py", line 555, in process_update
    handler.handle_update(update, self, check, context)
  File "C:\Users\STUD\AppData\Local\Programs\Python\Python37\lib\site-packages\telegram\ext\handler.py", line 198, in handle_update
    return self.callback(update, context)
  File "C:/Users/STUD/Documents/GitHub/BCA-SEM-6/PROGRAM/PYTHON/telebot/telebot.py", line 54, in start
    update.message.reply_text(u'Welcome to the best Url shortener\nJust send me a link and I\'ll shorten it.')
AttributeError: 'CallbackContext' object has no attribute 'message'

During handling of the above exception, another exception occurred:

Traceback (most recent call last):
  File "C:\Users\STUD\AppData\Local\Programs\Python\Python37\lib\site-packages\telegram\ext\dispatcher.py", line 567, in process_update
    self.dispatch_error(update, exc)
  File "C:\Users\STUD\AppData\Local\Programs\Python\Python37\lib\site-packages\telegram\ext\dispatcher.py", line 810, in dispatch_error
    callback(update, context)
TypeError: error() missing 1 required positional argument: 'error'
2022-02-17 11:17:01,547 - telegram.ext.dispatcher - ERROR - An uncaught error was raised while handling the error.
Traceback (most recent call last):
  File "C:\Users\STUD\AppData\Local\Programs\Python\Python37\lib\site-packages\telegram\ext\dispatcher.py", line 555, in process_update
    handler.handle_update(update, self, check, context)
  File "C:\Users\STUD\AppData\Local\Programs\Python\Python37\lib\site-packages\telegram\ext\handler.py", line 198, in handle_update
    return self.callback(update, context)
  File "C:/Users/STUD/Documents/GitHub/BCA-SEM-6/PROGRAM/PYTHON/telebot/telebot.py", line 58, in insert
    user = update.message.from_user
AttributeError: 'CallbackContext' object has no attribute 'message'

During handling of the above exception, another exception occurred:

Traceback (most recent call last):
  File "C:\Users\STUD\AppData\Local\Programs\Python\Python37\lib\site-packages\telegram\ext\dispatcher.py", line 567, in process_update
    self.dispatch_error(update, exc)
  File "C:\Users\STUD\AppData\Local\Programs\Python\Python37\lib\site-packages\telegram\ext\dispatcher.py", line 810, in dispatch_error
    callback(update, context)
TypeError: error() missing 1 required positional argument: 'error'
2022-02-17 11:18:45,064 - apscheduler.scheduler - INFO - Scheduler started
2022-02-17 11:18:48,401 - telegram.ext.dispatcher - ERROR - An uncaught error was raised while handling the error.
Traceback (most recent call last):
  File "C:\Users\STUD\AppData\Local\Programs\Python\Python37\lib\site-packages\telegram\ext\dispatcher.py", line 555, in process_update
    handler.handle_update(update, self, check, context)
  File "C:\Users\STUD\AppData\Local\Programs\Python\Python37\lib\site-packages\telegram\ext\handler.py", line 198, in handle_update
    return self.callback(update, context)
  File "C:/Users/STUD/Documents/GitHub/BCA-SEM-6/PROGRAM/PYTHON/telebot/telebot.py", line 55, in start
    Update.message.reply_text(u'Welcome to the best Url shortener\nJust send me a link and I\'ll shorten it.')
AttributeError: 'CallbackContext' object has no attribute 'message'

During handling of the above exception, another exception occurred:

Traceback (most recent call last):
  File "C:\Users\STUD\AppData\Local\Programs\Python\Python37\lib\site-packages\telegram\ext\dispatcher.py", line 567, in process_update
    self.dispatch_error(update, exc)
  File "C:\Users\STUD\AppData\Local\Programs\Python\Python37\lib\site-packages\telegram\ext\dispatcher.py", line 810, in dispatch_error
    callback(update, context)
TypeError: error() missing 1 required positional argument: 'error'
2022-02-17 11:18:50,205 - telegram.ext.dispatcher - ERROR - An uncaught error was raised while handling the error.
Traceback (most recent call last):
  File "C:\Users\STUD\AppData\Local\Programs\Python\Python37\lib\site-packages\telegram\ext\dispatcher.py", line 555, in process_update
    handler.handle_update(update, self, check, context)
  File "C:\Users\STUD\AppData\Local\Programs\Python\Python37\lib\site-packages\telegram\ext\handler.py", line 198, in handle_update
    return self.callback(update, context)
  File "C:/Users/STUD/Documents/GitHub/BCA-SEM-6/PROGRAM/PYTHON/telebot/telebot.py", line 55, in start
    Update.message.reply_text(u'Welcome to the best Url shortener\nJust send me a link and I\'ll shorten it.')
AttributeError: 'CallbackContext' object has no attribute 'message'

During handling of the above exception, another exception occurred:

Traceback (most recent call last):
  File "C:\Users\STUD\AppData\Local\Programs\Python\Python37\lib\site-packages\telegram\ext\dispatcher.py", line 567, in process_update
    self.dispatch_error(update, exc)
  File "C:\Users\STUD\AppData\Local\Programs\Python\Python37\lib\site-packages\telegram\ext\dispatcher.py", line 810, in dispatch_error
    callback(update, context)
TypeError: error() missing 1 required positional argument: 'error'
2022-02-17 11:20:46,149 - apscheduler.scheduler - INFO - Scheduler started
2022-02-17 11:20:57,978 - telegram.ext.dispatcher - ERROR - An uncaught error was raised while handling the error.
Traceback (most recent call last):
  File "C:\Users\STUD\AppData\Local\Programs\Python\Python37\lib\site-packages\telegram\ext\dispatcher.py", line 555, in process_update
    handler.handle_update(update, self, check, context)
  File "C:\Users\STUD\AppData\Local\Programs\Python\Python37\lib\site-packages\telegram\ext\handler.py", line 198, in handle_update
    return self.callback(update, context)
  File "C:/Users/STUD/Documents/GitHub/BCA-SEM-6/PROGRAM/PYTHON/telebot/telebot.py", line 56, in start
    Update.message.reply_text(u'Welcome to the best Url shortener\nJust send me a link and I\'ll shorten it.')
AttributeError: 'CallbackContext' object has no attribute 'message'

During handling of the above exception, another exception occurred:

Traceback (most recent call last):
  File "C:\Users\STUD\AppData\Local\Programs\Python\Python37\lib\site-packages\telegram\ext\dispatcher.py", line 567, in process_update
    self.dispatch_error(update, exc)
  File "C:\Users\STUD\AppData\Local\Programs\Python\Python37\lib\site-packages\telegram\ext\dispatcher.py", line 810, in dispatch_error
    callback(update, context)
TypeError: error() missing 1 required positional argument: 'error'
2022-02-17 11:21:25,349 - apscheduler.scheduler - INFO - Scheduler started
2022-02-17 11:21:28,406 - telegram.ext.dispatcher - ERROR - An uncaught error was raised while handling the error.
Traceback (most recent call last):
  File "C:\Users\STUD\AppData\Local\Programs\Python\Python37\lib\site-packages\telegram\ext\dispatcher.py", line 555, in process_update
    handler.handle_update(update, self, check, context)
  File "C:\Users\STUD\AppData\Local\Programs\Python\Python37\lib\site-packages\telegram\ext\handler.py", line 198, in handle_update
    return self.callback(update, context)
  File "C:/Users/STUD/Documents/GitHub/BCA-SEM-6/PROGRAM/PYTHON/telebot/telebot.py", line 56, in start
    print(Update.message.text)
AttributeError: 'CallbackContext' object has no attribute 'message'

During handling of the above exception, another exception occurred:

Traceback (most recent call last):
  File "C:\Users\STUD\AppData\Local\Programs\Python\Python37\lib\site-packages\telegram\ext\dispatcher.py", line 567, in process_update
    self.dispatch_error(update, exc)
  File "C:\Users\STUD\AppData\Local\Programs\Python\Python37\lib\site-packages\telegram\ext\dispatcher.py", line 810, in dispatch_error
    callback(update, context)
TypeError: error() missing 1 required positional argument: 'error'
2022-02-17 11:21:47,159 - apscheduler.scheduler - INFO - Scheduler started
2022-02-17 11:21:50,328 - telegram.ext.dispatcher - ERROR - An uncaught error was raised while handling the error.
Traceback (most recent call last):
  File "C:\Users\STUD\AppData\Local\Programs\Python\Python37\lib\site-packages\telegram\ext\dispatcher.py", line 555, in process_update
    handler.handle_update(update, self, check, context)
  File "C:\Users\STUD\AppData\Local\Programs\Python\Python37\lib\site-packages\telegram\ext\handler.py", line 198, in handle_update
    return self.callback(update, context)
  File "C:/Users/STUD/Documents/GitHub/BCA-SEM-6/PROGRAM/PYTHON/telebot/telebot.py", line 56, in start
    print("Hellow:"+Update.message.text)
AttributeError: 'CallbackContext' object has no attribute 'message'

During handling of the above exception, another exception occurred:

Traceback (most recent call last):
  File "C:\Users\STUD\AppData\Local\Programs\Python\Python37\lib\site-packages\telegram\ext\dispatcher.py", line 567, in process_update
    self.dispatch_error(update, exc)
  File "C:\Users\STUD\AppData\Local\Programs\Python\Python37\lib\site-packages\telegram\ext\dispatcher.py", line 810, in dispatch_error
    callback(update, context)
TypeError: error() missing 1 required positional argument: 'error'
2022-02-17 11:22:02,440 - telegram.ext.dispatcher - ERROR - An uncaught error was raised while handling the error.
Traceback (most recent call last):
  File "C:\Users\STUD\AppData\Local\Programs\Python\Python37\lib\site-packages\telegram\ext\dispatcher.py", line 555, in process_update
    handler.handle_update(update, self, check, context)
  File "C:\Users\STUD\AppData\Local\Programs\Python\Python37\lib\site-packages\telegram\ext\handler.py", line 198, in handle_update
    return self.callback(update, context)
  File "C:/Users/STUD/Documents/GitHub/BCA-SEM-6/PROGRAM/PYTHON/telebot/telebot.py", line 56, in start
    print("Hellow:"+Update.message.text)
AttributeError: 'CallbackContext' object has no attribute 'message'

During handling of the above exception, another exception occurred:

Traceback (most recent call last):
  File "C:\Users\STUD\AppData\Local\Programs\Python\Python37\lib\site-packages\telegram\ext\dispatcher.py", line 567, in process_update
    self.dispatch_error(update, exc)
  File "C:\Users\STUD\AppData\Local\Programs\Python\Python37\lib\site-packages\telegram\ext\dispatcher.py", line 810, in dispatch_error
    callback(update, context)
TypeError: error() missing 1 required positional argument: 'error'
2022-02-17 11:22:50,248 - apscheduler.scheduler - INFO - Scheduler started
2022-02-17 11:22:54,698 - telegram.ext.dispatcher - ERROR - An uncaught error was raised while handling the error.
Traceback (most recent call last):
  File "C:\Users\STUD\AppData\Local\Programs\Python\Python37\lib\site-packages\telegram\ext\dispatcher.py", line 555, in process_update
    handler.handle_update(update, self, check, context)
  File "C:\Users\STUD\AppData\Local\Programs\Python\Python37\lib\site-packages\telegram\ext\handler.py", line 198, in handle_update
    return self.callback(update, context)
  File "C:/Users/STUD/Documents/GitHub/BCA-SEM-6/PROGRAM/PYTHON/telebot/telebot.py", line 60, in insert
    user = update.message.from_user
AttributeError: 'CallbackContext' object has no attribute 'message'

During handling of the above exception, another exception occurred:

Traceback (most recent call last):
  File "C:\Users\STUD\AppData\Local\Programs\Python\Python37\lib\site-packages\telegram\ext\dispatcher.py", line 567, in process_update
    self.dispatch_error(update, exc)
  File "C:\Users\STUD\AppData\Local\Programs\Python\Python37\lib\site-packages\telegram\ext\dispatcher.py", line 810, in dispatch_error
    callback(update, context)
TypeError: error() missing 1 required positional argument: 'error'
2022-02-17 11:23:03,879 - telegram.ext.dispatcher - ERROR - An uncaught error was raised while handling the error.
Traceback (most recent call last):
  File "C:\Users\STUD\AppData\Local\Programs\Python\Python37\lib\site-packages\telegram\ext\dispatcher.py", line 555, in process_update
    handler.handle_update(update, self, check, context)
  File "C:\Users\STUD\AppData\Local\Programs\Python\Python37\lib\site-packages\telegram\ext\handler.py", line 198, in handle_update
    return self.callback(update, context)
  File "C:/Users/STUD/Documents/GitHub/BCA-SEM-6/PROGRAM/PYTHON/telebot/telebot.py", line 55, in start
    print("Hellow:"+Update.message.text)
AttributeError: 'CallbackContext' object has no attribute 'message'

During handling of the above exception, another exception occurred:

Traceback (most recent call last):
  File "C:\Users\STUD\AppData\Local\Programs\Python\Python37\lib\site-packages\telegram\ext\dispatcher.py", line 567, in process_update
    self.dispatch_error(update, exc)
  File "C:\Users\STUD\AppData\Local\Programs\Python\Python37\lib\site-packages\telegram\ext\dispatcher.py", line 810, in dispatch_error
    callback(update, context)
TypeError: error() missing 1 required positional argument: 'error'
2022-02-17 11:25:03,154 - apscheduler.scheduler - INFO - Scheduler started
2022-02-17 11:26:20,505 - apscheduler.scheduler - INFO - Scheduler started
2022-02-17 11:26:28,855 - telegram.ext.dispatcher - ERROR - An uncaught error was raised while handling the error.
Traceback (most recent call last):
  File "C:\Users\STUD\AppData\Local\Programs\Python\Python37\lib\site-packages\telegram\ext\dispatcher.py", line 555, in process_update
    handler.handle_update(update, self, check, context)
  File "C:\Users\STUD\AppData\Local\Programs\Python\Python37\lib\site-packages\telegram\ext\handler.py", line 198, in handle_update
    return self.callback(update, context)
  File "C:/Users/STUD/Documents/GitHub/BCA-SEM-6/PROGRAM/PYTHON/telebot/telebot.py", line 71, in insert
    invalid_link(bot, update)
  File "C:/Users/STUD/Documents/GitHub/BCA-SEM-6/PROGRAM/PYTHON/telebot/telebot.py", line 140, in invalid_link
    user = update.message.from_user
AttributeError: module 'telegram.bot' has no attribute 'message'

During handling of the above exception, another exception occurred:

Traceback (most recent call last):
  File "C:\Users\STUD\AppData\Local\Programs\Python\Python37\lib\site-packages\telegram\ext\dispatcher.py", line 567, in process_update
    self.dispatch_error(update, exc)
  File "C:\Users\STUD\AppData\Local\Programs\Python\Python37\lib\site-packages\telegram\ext\dispatcher.py", line 810, in dispatch_error
    callback(update, context)
TypeError: error() missing 1 required positional argument: 'error'
2022-02-17 11:26:34,227 - telegram.ext.dispatcher - ERROR - An uncaught error was raised while handling the error.
Traceback (most recent call last):
  File "C:\Users\STUD\AppData\Local\Programs\Python\Python37\lib\site-packages\telegram\ext\dispatcher.py", line 555, in process_update
    handler.handle_update(update, self, check, context)
  File "C:\Users\STUD\AppData\Local\Programs\Python\Python37\lib\site-packages\telegram\ext\handler.py", line 198, in handle_update
    return self.callback(update, context)
  File "C:/Users/STUD/Documents/GitHub/BCA-SEM-6/PROGRAM/PYTHON/telebot/telebot.py", line 71, in insert
    invalid_link(bot, update)
  File "C:/Users/STUD/Documents/GitHub/BCA-SEM-6/PROGRAM/PYTHON/telebot/telebot.py", line 140, in invalid_link
    user = update.message.from_user
AttributeError: module 'telegram.bot' has no attribute 'message'

During handling of the above exception, another exception occurred:

Traceback (most recent call last):
  File "C:\Users\STUD\AppData\Local\Programs\Python\Python37\lib\site-packages\telegram\ext\dispatcher.py", line 567, in process_update
    self.dispatch_error(update, exc)
  File "C:\Users\STUD\AppData\Local\Programs\Python\Python37\lib\site-packages\telegram\ext\dispatcher.py", line 810, in dispatch_error
    callback(update, context)
TypeError: error() missing 1 required positional argument: 'error'
2022-02-17 11:26:43,589 - telegram.ext.dispatcher - ERROR - An uncaught error was raised while handling the error.
Traceback (most recent call last):
  File "C:\Users\STUD\AppData\Local\Programs\Python\Python37\lib\site-packages\telegram\ext\dispatcher.py", line 555, in process_update
    handler.handle_update(update, self, check, context)
  File "C:\Users\STUD\AppData\Local\Programs\Python\Python37\lib\site-packages\telegram\ext\handler.py", line 198, in handle_update
    return self.callback(update, context)
  File "C:/Users/STUD/Documents/GitHub/BCA-SEM-6/PROGRAM/PYTHON/telebot/telebot.py", line 85, in insert
    credentials = ServiceAccountCredentials.from_json_keyfile_name('/path/to/googleProject.json', scopes)
  File "C:\Users\STUD\AppData\Local\Programs\Python\Python37\lib\site-packages\oauth2client\service_account.py", line 219, in from_json_keyfile_name
    with open(filename, 'r') as file_obj:
FileNotFoundError: [Errno 2] No such file or directory: '/path/to/googleProject.json'

During handling of the above exception, another exception occurred:

Traceback (most recent call last):
  File "C:\Users\STUD\AppData\Local\Programs\Python\Python37\lib\site-packages\telegram\ext\dispatcher.py", line 567, in process_update
    self.dispatch_error(update, exc)
  File "C:\Users\STUD\AppData\Local\Programs\Python\Python37\lib\site-packages\telegram\ext\dispatcher.py", line 810, in dispatch_error
    callback(update, context)
TypeError: error() missing 1 required positional argument: 'error'
2022-02-17 11:28:17,081 - apscheduler.scheduler - INFO - Scheduler started
2022-02-17 11:28:25,016 - telegram.ext.dispatcher - ERROR - An uncaught error was raised while handling the error.
Traceback (most recent call last):
  File "C:\Users\STUD\AppData\Local\Programs\Python\Python37\lib\site-packages\telegram\ext\dispatcher.py", line 555, in process_update
    handler.handle_update(update, self, check, context)
  File "C:\Users\STUD\AppData\Local\Programs\Python\Python37\lib\site-packages\telegram\ext\handler.py", line 198, in handle_update
    return self.callback(update, context)
  File "C:/Users/STUD/Documents/GitHub/BCA-SEM-6/PROGRAM/PYTHON/telebot/telebot.py", line 71, in insert
    invalid_link(bot, update)
  File "C:/Users/STUD/Documents/GitHub/BCA-SEM-6/PROGRAM/PYTHON/telebot/telebot.py", line 140, in invalid_link
    user = update.message.from_user
AttributeError: module 'telegram.bot' has no attribute 'message'

During handling of the above exception, another exception occurred:

Traceback (most recent call last):
  File "C:\Users\STUD\AppData\Local\Programs\Python\Python37\lib\site-packages\telegram\ext\dispatcher.py", line 567, in process_update
    self.dispatch_error(update, exc)
  File "C:\Users\STUD\AppData\Local\Programs\Python\Python37\lib\site-packages\telegram\ext\dispatcher.py", line 810, in dispatch_error
    callback(update, context)
TypeError: error() missing 1 required positional argument: 'error'
2022-02-17 11:28:29,255 - telegram.ext.dispatcher - ERROR - An uncaught error was raised while handling the error.
Traceback (most recent call last):
  File "C:\Users\STUD\AppData\Local\Programs\Python\Python37\lib\site-packages\telegram\ext\dispatcher.py", line 555, in process_update
    handler.handle_update(update, self, check, context)
  File "C:\Users\STUD\AppData\Local\Programs\Python\Python37\lib\site-packages\telegram\ext\handler.py", line 198, in handle_update
    return self.callback(update, context)
  File "C:/Users/STUD/Documents/GitHub/BCA-SEM-6/PROGRAM/PYTHON/telebot/telebot.py", line 71, in insert
    invalid_link(bot, update)
  File "C:/Users/STUD/Documents/GitHub/BCA-SEM-6/PROGRAM/PYTHON/telebot/telebot.py", line 140, in invalid_link
    user = update.message.from_user
AttributeError: module 'telegram.bot' has no attribute 'message'

During handling of the above exception, another exception occurred:

Traceback (most recent call last):
  File "C:\Users\STUD\AppData\Local\Programs\Python\Python37\lib\site-packages\telegram\ext\dispatcher.py", line 567, in process_update
    self.dispatch_error(update, exc)
  File "C:\Users\STUD\AppData\Local\Programs\Python\Python37\lib\site-packages\telegram\ext\dispatcher.py", line 810, in dispatch_error
    callback(update, context)
TypeError: error() missing 1 required positional argument: 'error'
2022-02-17 11:28:35,262 - telegram.ext.dispatcher - ERROR - An uncaught error was raised while handling the error.
Traceback (most recent call last):
  File "C:\Users\STUD\AppData\Local\Programs\Python\Python37\lib\site-packages\telegram\ext\dispatcher.py", line 555, in process_update
    handler.handle_update(update, self, check, context)
  File "C:\Users\STUD\AppData\Local\Programs\Python\Python37\lib\site-packages\telegram\ext\handler.py", line 198, in handle_update
    return self.callback(update, context)
  File "C:/Users/STUD/Documents/GitHub/BCA-SEM-6/PROGRAM/PYTHON/telebot/telebot.py", line 85, in insert
    credentials = ServiceAccountCredentials.from_json_keyfile_name('/path/to/googleProject.json', scopes)
  File "C:\Users\STUD\AppData\Local\Programs\Python\Python37\lib\site-packages\oauth2client\service_account.py", line 219, in from_json_keyfile_name
    with open(filename, 'r') as file_obj:
FileNotFoundError: [Errno 2] No such file or directory: '/path/to/googleProject.json'

During handling of the above exception, another exception occurred:

Traceback (most recent call last):
  File "C:\Users\STUD\AppData\Local\Programs\Python\Python37\lib\site-packages\telegram\ext\dispatcher.py", line 567, in process_update
    self.dispatch_error(update, exc)
  File "C:\Users\STUD\AppData\Local\Programs\Python\Python37\lib\site-packages\telegram\ext\dispatcher.py", line 810, in dispatch_error
    callback(update, context)
TypeError: error() missing 1 required positional argument: 'error'
2022-02-17 11:30:03,052 - apscheduler.scheduler - INFO - Scheduler started
2022-02-17 11:30:11,147 - telegram.ext.dispatcher - ERROR - An uncaught error was raised while handling the error.
Traceback (most recent call last):
  File "C:\Users\STUD\AppData\Local\Programs\Python\Python37\lib\site-packages\telegram\ext\dispatcher.py", line 555, in process_update
    handler.handle_update(update, self, check, context)
  File "C:\Users\STUD\AppData\Local\Programs\Python\Python37\lib\site-packages\telegram\ext\handler.py", line 198, in handle_update
    return self.callback(update, context)
  File "C:/Users/STUD/Documents/GitHub/BCA-SEM-6/PROGRAM/PYTHON/telebot/telebot.py", line 66, in insert
    print(user+text+caption)
TypeError: unsupported operand type(s) for +: 'User' and 'str'

During handling of the above exception, another exception occurred:

Traceback (most recent call last):
  File "C:\Users\STUD\AppData\Local\Programs\Python\Python37\lib\site-packages\telegram\ext\dispatcher.py", line 567, in process_update
    self.dispatch_error(update, exc)
  File "C:\Users\STUD\AppData\Local\Programs\Python\Python37\lib\site-packages\telegram\ext\dispatcher.py", line 810, in dispatch_error
    callback(update, context)
TypeError: error() missing 1 required positional argument: 'error'
2022-02-17 11:30:32,336 - apscheduler.scheduler - INFO - Scheduler started
2022-02-17 11:30:41,957 - telegram.ext.dispatcher - ERROR - An uncaught error was raised while handling the error.
Traceback (most recent call last):
  File "C:\Users\STUD\AppData\Local\Programs\Python\Python37\lib\site-packages\telegram\ext\dispatcher.py", line 555, in process_update
    handler.handle_update(update, self, check, context)
  File "C:\Users\STUD\AppData\Local\Programs\Python\Python37\lib\site-packages\telegram\ext\handler.py", line 198, in handle_update
    return self.callback(update, context)
  File "C:/Users/STUD/Documents/GitHub/BCA-SEM-6/PROGRAM/PYTHON/telebot/telebot.py", line 67, in insert
    print(user+text+caption)
TypeError: unsupported operand type(s) for +: 'User' and 'str'

During handling of the above exception, another exception occurred:

Traceback (most recent call last):
  File "C:\Users\STUD\AppData\Local\Programs\Python\Python37\lib\site-packages\telegram\ext\dispatcher.py", line 567, in process_update
    self.dispatch_error(update, exc)
  File "C:\Users\STUD\AppData\Local\Programs\Python\Python37\lib\site-packages\telegram\ext\dispatcher.py", line 810, in dispatch_error
    callback(update, context)
TypeError: error() missing 1 required positional argument: 'error'
2022-02-17 11:31:59,449 - apscheduler.scheduler - INFO - Scheduler started
2022-02-17 11:32:07,258 - telegram.ext.dispatcher - ERROR - An uncaught error was raised while handling the error.
Traceback (most recent call last):
  File "C:\Users\STUD\AppData\Local\Programs\Python\Python37\lib\site-packages\telegram\ext\dispatcher.py", line 555, in process_update
    handler.handle_update(update, self, check, context)
  File "C:\Users\STUD\AppData\Local\Programs\Python\Python37\lib\site-packages\telegram\ext\handler.py", line 198, in handle_update
    return self.callback(update, context)
  File "C:/Users/STUD/Documents/GitHub/BCA-SEM-6/PROGRAM/PYTHON/telebot/telebot.py", line 67, in insert
    print(user+text+caption)
TypeError: unsupported operand type(s) for +: 'User' and 'str'

During handling of the above exception, another exception occurred:

Traceback (most recent call last):
  File "C:\Users\STUD\AppData\Local\Programs\Python\Python37\lib\site-packages\telegram\ext\dispatcher.py", line 567, in process_update
    self.dispatch_error(update, exc)
  File "C:\Users\STUD\AppData\Local\Programs\Python\Python37\lib\site-packages\telegram\ext\dispatcher.py", line 810, in dispatch_error
    callback(update, context)
TypeError: error() missing 1 required positional argument: 'error'
2022-02-17 11:32:39,497 - apscheduler.scheduler - INFO - Scheduler started
2022-02-17 11:33:04,729 - apscheduler.scheduler - INFO - Scheduler started
2022-02-17 11:33:10,971 - telegram.ext.dispatcher - ERROR - An uncaught error was raised while handling the error.
Traceback (most recent call last):
  File "C:\Users\STUD\AppData\Local\Programs\Python\Python37\lib\site-packages\telegram\ext\dispatcher.py", line 555, in process_update
    handler.handle_update(update, self, check, context)
  File "C:\Users\STUD\AppData\Local\Programs\Python\Python37\lib\site-packages\telegram\ext\handler.py", line 198, in handle_update
    return self.callback(update, context)
  File "C:/Users/STUD/Documents/GitHub/BCA-SEM-6/PROGRAM/PYTHON/telebot/telebot.py", line 89, in insert
    credentials = ServiceAccountCredentials.from_json_keyfile_name('/path/to/googleProject.json', scopes)
  File "C:\Users\STUD\AppData\Local\Programs\Python\Python37\lib\site-packages\oauth2client\service_account.py", line 219, in from_json_keyfile_name
    with open(filename, 'r') as file_obj:
FileNotFoundError: [Errno 2] No such file or directory: '/path/to/googleProject.json'

During handling of the above exception, another exception occurred:

Traceback (most recent call last):
  File "C:\Users\STUD\AppData\Local\Programs\Python\Python37\lib\site-packages\telegram\ext\dispatcher.py", line 567, in process_update
    self.dispatch_error(update, exc)
  File "C:\Users\STUD\AppData\Local\Programs\Python\Python37\lib\site-packages\telegram\ext\dispatcher.py", line 810, in dispatch_error
    callback(update, context)
TypeError: error() missing 1 required positional argument: 'error'
2022-02-17 11:33:58,320 - apscheduler.scheduler - INFO - Scheduler started
2022-02-17 11:34:01,675 - telegram.ext.dispatcher - ERROR - An uncaught error was raised while handling the error.
Traceback (most recent call last):
  File "C:\Users\STUD\AppData\Local\Programs\Python\Python37\lib\site-packages\telegram\ext\dispatcher.py", line 555, in process_update
    handler.handle_update(update, self, check, context)
  File "C:\Users\STUD\AppData\Local\Programs\Python\Python37\lib\site-packages\telegram\ext\handler.py", line 198, in handle_update
    return self.callback(update, context)
  File "C:/Users/STUD/Documents/GitHub/BCA-SEM-6/PROGRAM/PYTHON/telebot/telebot.py", line 64, in insert
    print(update.message.text+"\n"+update.message.caption)
TypeError: can only concatenate str (not "NoneType") to str

During handling of the above exception, another exception occurred:

Traceback (most recent call last):
  File "C:\Users\STUD\AppData\Local\Programs\Python\Python37\lib\site-packages\telegram\ext\dispatcher.py", line 567, in process_update
    self.dispatch_error(update, exc)
  File "C:\Users\STUD\AppData\Local\Programs\Python\Python37\lib\site-packages\telegram\ext\dispatcher.py", line 810, in dispatch_error
    callback(update, context)
TypeError: error() missing 1 required positional argument: 'error'
2022-02-17 11:34:11,978 - telegram.ext.dispatcher - ERROR - An uncaught error was raised while handling the error.
Traceback (most recent call last):
  File "C:\Users\STUD\AppData\Local\Programs\Python\Python37\lib\site-packages\telegram\ext\dispatcher.py", line 555, in process_update
    handler.handle_update(update, self, check, context)
  File "C:\Users\STUD\AppData\Local\Programs\Python\Python37\lib\site-packages\telegram\ext\handler.py", line 198, in handle_update
    return self.callback(update, context)
  File "C:/Users/STUD/Documents/GitHub/BCA-SEM-6/PROGRAM/PYTHON/telebot/telebot.py", line 64, in insert
    print(update.message.text+"\n"+update.message.caption)
TypeError: can only concatenate str (not "NoneType") to str

During handling of the above exception, another exception occurred:

Traceback (most recent call last):
  File "C:\Users\STUD\AppData\Local\Programs\Python\Python37\lib\site-packages\telegram\ext\dispatcher.py", line 567, in process_update
    self.dispatch_error(update, exc)
  File "C:\Users\STUD\AppData\Local\Programs\Python\Python37\lib\site-packages\telegram\ext\dispatcher.py", line 810, in dispatch_error
    callback(update, context)
TypeError: error() missing 1 required positional argument: 'error'
2022-02-17 11:34:41,102 - apscheduler.scheduler - INFO - Scheduler started
2022-02-17 11:34:44,711 - telegram.ext.dispatcher - ERROR - An uncaught error was raised while handling the error.
Traceback (most recent call last):
  File "C:\Users\STUD\AppData\Local\Programs\Python\Python37\lib\site-packages\telegram\ext\dispatcher.py", line 555, in process_update
    handler.handle_update(update, self, check, context)
  File "C:\Users\STUD\AppData\Local\Programs\Python\Python37\lib\site-packages\telegram\ext\handler.py", line 198, in handle_update
    return self.callback(update, context)
  File "C:/Users/STUD/Documents/GitHub/BCA-SEM-6/PROGRAM/PYTHON/telebot/telebot.py", line 90, in insert
    credentials = ServiceAccountCredentials.from_json_keyfile_name('/path/to/googleProject.json', scopes)
  File "C:\Users\STUD\AppData\Local\Programs\Python\Python37\lib\site-packages\oauth2client\service_account.py", line 219, in from_json_keyfile_name
    with open(filename, 'r') as file_obj:
FileNotFoundError: [Errno 2] No such file or directory: '/path/to/googleProject.json'

During handling of the above exception, another exception occurred:

Traceback (most recent call last):
  File "C:\Users\STUD\AppData\Local\Programs\Python\Python37\lib\site-packages\telegram\ext\dispatcher.py", line 567, in process_update
    self.dispatch_error(update, exc)
  File "C:\Users\STUD\AppData\Local\Programs\Python\Python37\lib\site-packages\telegram\ext\dispatcher.py", line 810, in dispatch_error
    callback(update, context)
TypeError: error() missing 1 required positional argument: 'error'
2022-02-17 11:34:58,922 - telegram.ext.dispatcher - ERROR - An uncaught error was raised while handling the error.
Traceback (most recent call last):
  File "C:\Users\STUD\AppData\Local\Programs\Python\Python37\lib\site-packages\telegram\ext\dispatcher.py", line 555, in process_update
    handler.handle_update(update, self, check, context)
  File "C:\Users\STUD\AppData\Local\Programs\Python\Python37\lib\site-packages\telegram\ext\handler.py", line 198, in handle_update
    return self.callback(update, context)
  File "C:/Users/STUD/Documents/GitHub/BCA-SEM-6/PROGRAM/PYTHON/telebot/telebot.py", line 90, in insert
    credentials = ServiceAccountCredentials.from_json_keyfile_name('/path/to/googleProject.json', scopes)
  File "C:\Users\STUD\AppData\Local\Programs\Python\Python37\lib\site-packages\oauth2client\service_account.py", line 219, in from_json_keyfile_name
    with open(filename, 'r') as file_obj:
FileNotFoundError: [Errno 2] No such file or directory: '/path/to/googleProject.json'

During handling of the above exception, another exception occurred:

Traceback (most recent call last):
  File "C:\Users\STUD\AppData\Local\Programs\Python\Python37\lib\site-packages\telegram\ext\dispatcher.py", line 567, in process_update
    self.dispatch_error(update, exc)
  File "C:\Users\STUD\AppData\Local\Programs\Python\Python37\lib\site-packages\telegram\ext\dispatcher.py", line 810, in dispatch_error
    callback(update, context)
TypeError: error() missing 1 required positional argument: 'error'
2022-02-17 11:38:10,331 - apscheduler.scheduler - INFO - Scheduler started
2022-02-17 11:39:06,892 - apscheduler.scheduler - INFO - Scheduler started
2022-02-17 11:39:20,298 - telegram.ext.dispatcher - ERROR - An uncaught error was raised while handling the error.
Traceback (most recent call last):
  File "C:\Users\STUD\AppData\Local\Programs\Python\Python37\lib\site-packages\telegram\ext\dispatcher.py", line 555, in process_update
    handler.handle_update(update, self, check, context)
  File "C:\Users\STUD\AppData\Local\Programs\Python\Python37\lib\site-packages\telegram\ext\handler.py", line 198, in handle_update
    return self.callback(update, context)
  File "C:/Users/STUD/Documents/GitHub/BCA-SEM-6/PROGRAM/PYTHON/telebot/telebot.py", line 93, in insert
    credentials = ServiceAccountCredentials.from_json_keyfile_name('/path/to/googleProject.json', scopes)
  File "C:\Users\STUD\AppData\Local\Programs\Python\Python37\lib\site-packages\oauth2client\service_account.py", line 219, in from_json_keyfile_name
    with open(filename, 'r') as file_obj:
FileNotFoundError: [Errno 2] No such file or directory: '/path/to/googleProject.json'

During handling of the above exception, another exception occurred:

Traceback (most recent call last):
  File "C:\Users\STUD\AppData\Local\Programs\Python\Python37\lib\site-packages\telegram\ext\dispatcher.py", line 567, in process_update
    self.dispatch_error(update, exc)
  File "C:\Users\STUD\AppData\Local\Programs\Python\Python37\lib\site-packages\telegram\ext\dispatcher.py", line 810, in dispatch_error
    callback(update, context)
TypeError: error() missing 1 required positional argument: 'error'
2022-02-17 11:40:28,577 - apscheduler.scheduler - INFO - Scheduler started
2022-02-17 11:40:31,932 - telegram.ext.dispatcher - ERROR - An uncaught error was raised while handling the error.
Traceback (most recent call last):
  File "C:\Users\STUD\AppData\Local\Programs\Python\Python37\lib\site-packages\telegram\ext\dispatcher.py", line 555, in process_update
    handler.handle_update(update, self, check, context)
  File "C:\Users\STUD\AppData\Local\Programs\Python\Python37\lib\site-packages\telegram\ext\handler.py", line 198, in handle_update
    return self.callback(update, context)
  File "C:/Users/STUD/Documents/GitHub/BCA-SEM-6/PROGRAM/PYTHON/telebot/telebot.py", line 95, in insert
    credentials = ServiceAccountCredentials.from_json_keyfile_name('/path/to/googleProject.json', scopes)
  File "C:\Users\STUD\AppData\Local\Programs\Python\Python37\lib\site-packages\oauth2client\service_account.py", line 219, in from_json_keyfile_name
    with open(filename, 'r') as file_obj:
FileNotFoundError: [Errno 2] No such file or directory: '/path/to/googleProject.json'

During handling of the above exception, another exception occurred:

Traceback (most recent call last):
  File "C:\Users\STUD\AppData\Local\Programs\Python\Python37\lib\site-packages\telegram\ext\dispatcher.py", line 567, in process_update
    self.dispatch_error(update, exc)
  File "C:\Users\STUD\AppData\Local\Programs\Python\Python37\lib\site-packages\telegram\ext\dispatcher.py", line 810, in dispatch_error
    callback(update, context)
TypeError: error() missing 1 required positional argument: 'error'
2022-02-17 11:40:52,960 - apscheduler.scheduler - INFO - Scheduler started
2022-02-17 11:40:56,362 - telegram.ext.dispatcher - ERROR - An uncaught error was raised while handling the error.
Traceback (most recent call last):
  File "C:\Users\STUD\AppData\Local\Programs\Python\Python37\lib\site-packages\telegram\ext\dispatcher.py", line 555, in process_update
    handler.handle_update(update, self, check, context)
  File "C:\Users\STUD\AppData\Local\Programs\Python\Python37\lib\site-packages\telegram\ext\handler.py", line 198, in handle_update
    return self.callback(update, context)
  File "C:/Users/STUD/Documents/GitHub/BCA-SEM-6/PROGRAM/PYTHON/telebot/telebot.py", line 96, in insert
    credentials = ServiceAccountCredentials.from_json_keyfile_name('/path/to/googleProject.json', scopes)
  File "C:\Users\STUD\AppData\Local\Programs\Python\Python37\lib\site-packages\oauth2client\service_account.py", line 219, in from_json_keyfile_name
    with open(filename, 'r') as file_obj:
FileNotFoundError: [Errno 2] No such file or directory: '/path/to/googleProject.json'

During handling of the above exception, another exception occurred:

Traceback (most recent call last):
  File "C:\Users\STUD\AppData\Local\Programs\Python\Python37\lib\site-packages\telegram\ext\dispatcher.py", line 567, in process_update
    self.dispatch_error(update, exc)
  File "C:\Users\STUD\AppData\Local\Programs\Python\Python37\lib\site-packages\telegram\ext\dispatcher.py", line 810, in dispatch_error
    callback(update, context)
TypeError: error() missing 1 required positional argument: 'error'
